[32m2025-08-20 10:34:47 -0400[0m - dagster - [34mDEBUG[0m - __ASSET_JOB - 4f7a2e6f-c0b8-4cdf-b713-b41909d9c98d - 78873 - LOGS_CAPTURED - Started capturing logs in process (pid: 78873).
[32m2025-08-20 10:34:47 -0400[0m - dagster - [34mDEBUG[0m - __ASSET_JOB - 4f7a2e6f-c0b8-4cdf-b713-b41909d9c98d - 78873 - datastack_dbt_assets - STEP_START - Started execution of step "datastack_dbt_assets".
[32m2025-08-20 10:34:47 -0400[0m - dagster - [34mERROR[0m - [31m__ASSET_JOB - 4f7a2e6f-c0b8-4cdf-b713-b41909d9c98d - 78873 - datastack_dbt_assets - STEP_FAILURE - Execution of step "datastack_dbt_assets" failed.

dagster._core.errors.DagsterUnknownResourceError: Unknown resource `dbt`. Specify `dbt` as a required resource on the compute / config function that accessed it.

Stack Trace:
  File "/Users/op/Desktop/data-stack-exercise/data-stack-exercise/datastack-env/lib/python3.13/site-packages/dagster/_core/execution/plan/execute_plan.py", line 246, in dagster_event_sequence_for_step
    yield from check.generator(step_events)
  File "/Users/op/Desktop/data-stack-exercise/data-stack-exercise/datastack-env/lib/python3.13/site-packages/dagster/_core/execution/plan/execute_step.py", line 504, in core_dagster_event_sequence_for_step
    for user_event in _step_output_error_checked_user_event_sequence(
                      ~~~~~~~~~~~~~~~~~~~~~~~~~~~~~~~~~~~~~~~~~~~~~~^
        step_context,
        ^^^^^^^^^^^^^
        _process_asset_results_to_events(step_context, user_event_sequence),
        ^^^^^^^^^^^^^^^^^^^^^^^^^^^^^^^^^^^^^^^^^^^^^^^^^^^^^^^^^^^^^^^^^^^^
    ):
    ^
  File "/Users/op/Desktop/data-stack-exercise/data-stack-exercise/datastack-env/lib/python3.13/site-packages/dagster/_core/execution/plan/execute_step.py", line 183, in _step_output_error_checked_user_event_sequence
    for user_event in user_event_sequence:
                      ^^^^^^^^^^^^^^^^^^^
  File "/Users/op/Desktop/data-stack-exercise/data-stack-exercise/datastack-env/lib/python3.13/site-packages/dagster/_core/execution/plan/execute_step.py", line 88, in _process_asset_results_to_events
    for user_event in user_event_sequence:
                      ^^^^^^^^^^^^^^^^^^^
  File "/Users/op/Desktop/data-stack-exercise/data-stack-exercise/datastack-env/lib/python3.13/site-packages/dagster/_core/execution/plan/compute.py", line 190, in execute_core_compute
    for step_output in _yield_compute_results(step_context, inputs, compute_fn, compute_context):
                       ~~~~~~~~~~~~~~~~~~~~~~^^^^^^^^^^^^^^^^^^^^^^^^^^^^^^^^^^^^^^^^^^^^^^^^^^^
  File "/Users/op/Desktop/data-stack-exercise/data-stack-exercise/datastack-env/lib/python3.13/site-packages/dagster/_core/execution/plan/compute.py", line 159, in _yield_compute_results
    for event in iterate_with_context(
                 ~~~~~~~~~~~~~~~~~~~~^
        lambda: op_execution_error_boundary(
        ^^^^^^^^^^^^^^^^^^^^^^^^^^^^^^^^^^^^
    ...<7 lines>...
        user_event_generator,
        ^^^^^^^^^^^^^^^^^^^^^
    ):
    ^
  File "/Users/op/Desktop/data-stack-exercise/data-stack-exercise/datastack-env/lib/python3.13/site-packages/dagster/_utils/__init__.py", line 392, in iterate_with_context
    next_output = next(iterator)
  File "/Users/op/Desktop/data-stack-exercise/data-stack-exercise/modern-data-stack/dagster_project/datastack_orchestration/datastack_orchestration/assets.py", line 23, in datastack_dbt_assets
    yield from context.resources.dbt.cli(["build"], context=context).stream()
               ^^^^^^^^^^^^^^^^^^^^^
  File "/Users/op/Desktop/data-stack-exercise/data-stack-exercise/datastack-env/lib/python3.13/site-packages/dagster/_core/definitions/scoped_resources_builder.py", line 30, in __getattr__
    raise DagsterUnknownResourceError(name)
[0m
